









Training | Epoch: 0 | Loss: 11291928.0569 | :   0%|          | 261/67569 [00:21<1:33:31, 11.99it/s]
Traceback (most recent call last):
  File "/net/vast-storage.ib.cluster/scratch/user/valmiki/stats_lecture/src/price_predictor/train.py", line 233, in <module>
    train(config)
  File "/net/vast-storage.ib.cluster/scratch/user/valmiki/stats_lecture/src/price_predictor/train.py", line 182, in train
    train_loss, train_acc = train_epoch(
                            ^^^^^^^^^^^^
  File "/net/vast-storage.ib.cluster/scratch/user/valmiki/stats_lecture/src/price_predictor/train.py", line 35, in train_epoch
    for i, seq in enumerate(bar):
  File "/om2/user/valmiki/miniconda/envs/pytorch/lib/python3.11/site-packages/tqdm/std.py", line 1181, in __iter__
    for obj in iterable:
  File "/om2/user/valmiki/miniconda/envs/pytorch/lib/python3.11/site-packages/torch/utils/data/dataloader.py", line 631, in __next__
    data = self._next_data()
           ^^^^^^^^^^^^^^^^^
  File "/om2/user/valmiki/miniconda/envs/pytorch/lib/python3.11/site-packages/torch/utils/data/dataloader.py", line 1346, in _next_data
    return self._process_data(data)
           ^^^^^^^^^^^^^^^^^^^^^^^^
  File "/om2/user/valmiki/miniconda/envs/pytorch/lib/python3.11/site-packages/torch/utils/data/dataloader.py", line 1372, in _process_data
    data.reraise()
  File "/om2/user/valmiki/miniconda/envs/pytorch/lib/python3.11/site-packages/torch/_utils.py", line 722, in reraise
    raise exception
RuntimeError: Caught RuntimeError in DataLoader worker process 1.
Original Traceback (most recent call last):
  File "/om2/user/valmiki/miniconda/envs/pytorch/lib/python3.11/site-packages/torch/utils/data/_utils/worker.py", line 308, in _worker_loop
    data = fetcher.fetch(index)
           ^^^^^^^^^^^^^^^^^^^^
  File "/om2/user/valmiki/miniconda/envs/pytorch/lib/python3.11/site-packages/torch/utils/data/_utils/fetch.py", line 54, in fetch
    return self.collate_fn(data)
           ^^^^^^^^^^^^^^^^^^^^^
  File "/om2/user/valmiki/miniconda/envs/pytorch/lib/python3.11/site-packages/torch/utils/data/_utils/collate.py", line 277, in default_collate
    return collate(batch, collate_fn_map=default_collate_fn_map)
           ^^^^^^^^^^^^^^^^^^^^^^^^^^^^^^^^^^^^^^^^^^^^^^^^^^^^^
  File "/om2/user/valmiki/miniconda/envs/pytorch/lib/python3.11/site-packages/torch/utils/data/_utils/collate.py", line 121, in collate
    return collate_fn_map[elem_type](batch, collate_fn_map=collate_fn_map)
           ^^^^^^^^^^^^^^^^^^^^^^^^^^^^^^^^^^^^^^^^^^^^^^^^^^^^^^^^^^^^^^^
  File "/om2/user/valmiki/miniconda/envs/pytorch/lib/python3.11/site-packages/torch/utils/data/_utils/collate.py", line 173, in collate_tensor_fn
    out = elem.new(storage).resize_(len(batch), *list(elem.size()))
          ^^^^^^^^^^^^^^^^^^^^^^^^^^^^^^^^^^^^^^^^^^^^^^^^^^^^^^^^^
RuntimeError: Trying to resize storage that is not resizable